Workbook

Sheet Inventario
A1: Instrucciones: Registra compras en 'Entradas' y usos en 'Salidas'. 'Stock actual' y 'Costo total' se calculan automáticamente.
A2: Insumo | B2: Categoría | C2: Unidad de medida | D2: Cantidad comprada | E2: Entradas | F2: Salidas | G2: Stock actual | H2: Costo unitario (S/) | I2: Costo total (S/)
B3: Materia prima | C3: kg | G3: =D3+E3-F3 -> 0 | H3: 45 | I3: =G3*H3 -> 0
B4: Fragancia | C4: ml | G4: =D4+E4-F4 -> 0 | H4: 0.6 | I4: =G4*H4 -> 0
B5: Envases | C5: unidad | G5: =D5+E5-F5 -> 0 | H5: 3 | I5: =G5*H5 -> 0
B6: Insumo | C6: unidad | G6: =D6+E6-F6 -> 0 | H6: 0.5 | I6: =G6*H6 -> 0
B7: Empaque | C7: unidad | G7: =D7+E7-F7 -> 0 | H7: 0.2 | I7: =G7*H7 -> 0
B8: Empaque | C8: unidad | G8: =D8+E8-F8 -> 0 | H8: 1.5 | I8: =G8*H8 -> 0

Sheet Costos Unitarios
B1: Instrucciones: Ingresa cantidad usada por vela y costo por unidad. 'Costo por vela' y el total se calculan solos.
A2: Código | B2: Insumo | C2: Cantidad usada | D2: Costo por unidad (S/) | E2: Costo por joya (S/) | H2: Fijos | K2: Variable
A3: CL02 | B3: Dije | C3: 2 | D3: 18 | E3: =C3*D3 -> 36 | G3: 2 | H3: Meta ads | I3: 500 | K3: Motorizado | L3: 8 | M3: por recojo
B4: Diseño | C4: 1 | D4: 20 | E4: =C4*D4 -> 20
B5: Impresión | C5: 1 | D5: 8 | E5: =C5*D5 -> 8 | H5: Web | I5: 34
B6: cadena pancer | C6: 1 | D6: 17 | E6: =C6*D6 -> 17
B7: Empaque | C7: 1 | D7: 3.5 | E7: =C7*D7 -> 3.5
B8: Papel Film | C8: =1/200 -> 0.005 | D8: 17 | E8: =C8*D8 -> 0.085
B9: Post It | C9: =1/40 -> 0.025 | D9: 3 | E9: =C9*D9 -> 0.075 | H9: Precio de plata 15.04
E10: =SUM(E3:E9) -> 84.66 | H10: 18 por plata trabaja en 950
D11: Costo total unitario | E11: 18
A12: CL01 | B12: Dije | C12: 1.5 | D12: 18 | E12: =C12*D12 -> 27
B13: Diseño e Impresión | C13: 1 | D13: 29 | E13: =C13*D13 -> 29
B14: cadena pancer | C14: 1 | D14: 17 | E14: =C14*D14 -> 17
B15: Empaque | C15: 1 | D15: 3.5 | E15: =C15*D15 -> 3.5
B16: Papel Film | C16: =1/200 -> 0.005 | D16: 17 | E16: =C16*D16 -> 0.085
B17: Post It | C17: =1/40 -> 0.025 | D17: 3 | E17: =C17*D17 -> 0.075
D18: Costo total unitario | E18: =SUM(E12:E17) -> 76.66
A20: PL01 | B20: Dije | C20: 1 | D20: 18 | E20: =C20*D20 -> 18 | G20: 2
B21: Diseño e Impresión | C21: 1 | D21: 29 | E21: =C21*D21 -> 29
B22: Tejido (hilo + MO) | C22: 1 | D22: 8 | E22: =C22*D22 -> 8
B23: Empaque | C23: 1 | D23: 3.5 | E23: =C23*D23 -> 3.5
B24: Papel Film | C24: =1/200 -> 0.005 | D24: 17 | E24: =C24*D24 -> 0.085
B25: Post It | C25: =1/40 -> 0.025 | D25: 3 | E25: =C25*D25 -> 0.075
D26: Costo total unitario | E26: =SUM(E20:E25) -> 58.66
A28: PL07 | B28: Dije | C28: 1 | D28: 31 | E28: =C28*D28 -> 31 | G28: 2.5
B29: Diseño e Impresión | C29: 1 | D29: =15+9 -> 24 | E29: =C29*D29 -> 24
B30: Tejido (cuerina + MO) | C30: 1 | D30: 12 | E30: =C30*D30 -> 12
B31: Empaque | C31: 1 | D31: 3.5 | E31: =C31*D31 -> 3.5
B32: Papel Film | C32: =1/200 -> 0.005 | D32: 17 | E32: =C32*D32 -> 0.085
B33: Post It | C33: =1/40 -> 0.025 | D33: 3 | E33: =C33*D33 -> 0.075
D34: Costo total unitario | E34: =SUM(E28:E33) -> 70.66
A36: PL08 | B36: Dije | C36: 1 | D36: 30 | E36: =C36*D36 -> 30 | G36: x
B37: Diseño e Impresión | C37: 1 | D37: =15+9 -> 24 | E37: =C37*D37 -> 24
B38: Cadena | C38: 1 | D38: 17 | E38: =C38*D38 -> 17
B39: Empaque | C39: 1 | D39: 3.5 | E39: =C39*D39 -> 3.5
B40: Papel Film | C40: =1/200 -> 0.005 | D40: 17 | E40: =C40*D40 -> 0.085
B41: Post It | C41: =1/40 -> 0.025 | D41: 3 | E41: =C41*D41 -> 0.075
D42: Costo total unitario | E42: =SUM(E36:E41) -> 74.66
A44: Huellita | B44: Dije | C44: 1 | D44: 30 | E44: =C44*D44 -> 30 | G44: 1.5
...

Sheet Copia de Costos Unitarios
A2: Código | B2: Insumo | C2: Cantidad usada | D2: Costo por unidad (S/) | E2: Costo por joya (S/) | F2: Hasta Dic 25 | H2: Fijos | K2: Variable
A3: CL01 | B3: Collar = cadena tipo pancer de 45cm +dije de 1.5cm colgante
B4: Dije | C4: 1 | D4: 34 | E4: =C4*D4 -> 34 | F4: 22 | H4: Meta ads | I4: 500 | K4: Motorizado | L4: 8 | M4: por recojo
B5: Diseño | C5: 1 | D5: 20 | E5: =C5*D5 -> 20
B6: Impresión | C6: 1 | D6: 8 | E6: =C6*D6 -> 8 | H6: Web | I6: 34
B7: cadena pancer | C7: 1 | D7: 25 | E7: =C7*D7 -> 25
B8: Empaque | C8: 1 | D8: 3.5 | E8: =C8*D8 -> 3.5
B9: Papel Film | C9: =1/200 -> 0.005 | D9: 17 | E9: =C9*D9 -> 0.085
B10: Post It | C10: =1/40 -> 0.025 | D10: 3 | E10: =C10*D10 -> 0.075 | K10: Precio de plata 15.04
K11: 18 por plata trabaja en 950
D12: Costo total unitario | E12: =SUM(E4:E10) -> 90.66
D13: PV | E13: =149 -> 149
D14: Comisiones 10% sobre PV | E14: =E13*0.1 -> 14.9
D15: IGV | E15: =E13*0.18 -> 26.82
A17: CL02 | B17: Collar = cadena tipo pancer de 45cm +dije de 2cm colgante
B18: Dije | C18: 1 | D18: 56 | E18: =C18*D18 -> 56 | F18: 34
B19: Diseño | C19: 1 | D19: 20 | E19: =C19*D19 -> 20
B20: Impresión | C20: 1 | D20: 9 | E20: =C20*D20 -> 9
B21: cadena pancer | C21: 1 | D21: 25 | E21: =C21*D21 -> 25
B22: Empaque | C22: 1 | D22: 3.5 | E22: =C22*D22 -> 3.5
B23: Papel Film | C23: =1/200 -> 0.005 | D23: 17 | E23: =C23*D23 -> 0.085
B24: Post It | C24: =1/40 -> 0.025 | D24: 3 | E24: =C24*D24 -> 0.075
D25: Costo total unitario | E25: =SUM(E18:E24) -> 113.66
D26: PV | E26: 169
D27: Comisiones 10% sobre PV | E27: =E26*0.1 -> 16.9
D28: IGV | E28: =E26-E27 -> 152.1
A30: P01 | B30: Dije | C30: 1 | D30: 56.1 | E30: =C30*D30 -> 56.1 | G30: 2
B31: Diseño e Impresión | C31: 1 | D31: 29 | E31: =C31*D31 -> 29
B32: Tejido hilo | C32: 1 | D32: 4 | E32: =C32*D32 -> 4
B33: MO
B34: Empaque | C34: 1 | D34: 3.5 | E34: =C34*D34 -> 3.5
B35: Papel Film | C35: =1/200 -> 0.005 | D35: 17 | E35: =C35*D35 -> 0.085
B36: Post It | C36: =1/40 -> 0.025 | D36: 3 | E36: =C36*D36 -> 0.075
D37: Costo total unitario | E37: =SUM(E29:E36) -> 92.76
D38: PV | E38: 149
D39: Comisiones 10% sobre PV | E39: =E38*0.1 -> 14.9
D40: IGV | E40: =E38-E39 -> 134.1
A42: PL07 | B42: Dije | C42: 1 | D42: 57.8 | E42: =C42*D42 -> 57.8
B43: Diseño e Impresión | C43: 1 | D43: =29 -> 29 | E43: =C43*D43 -> 29
B44: Tejido (cuerina + MO) | C44: 1 | D44: 12 | E44: =C44*D44 -> 12
...

Sheet Precios y Combos
A1: Instrucciones: Precios sugeridos con margen sobre el costo total unitario. Combos aplican descuento al precio con 50% margen.
A2: Margen | B2: Precio de venta (S/) | F2: Margen | G2: Precio de venta (S/)
A3: CL02 | F3: CL01
A4: 30% | B4: ='Costos Unitarios'!E10*1.3 -> 110.058 | F4: 30% | G4: ='Costos Unitarios'!$E$18*1.3 -> 99.658
A5: 40% | B5: ='Costos Unitarios'!E10*1.4 -> 118.524 | F5: 40% | G5: ='Costos Unitarios'!$E$18*1.4 -> 107.324
A6: 0.9 | B6: ='Costos Unitarios'!E10*1.9 -> 160.854 | F6: 0.9 | G6: ='Costos Unitarios'!$E$18*1.9 -> 145.654
A8: Combos | B8: Precio total (S/) | C8: Comisión | D8: Margen | F8: Combos | G8: Precio total (S/) | H8: Comisión | I8: Margen
A9: 2 collares (5% desc.) | B9: =(B14* 2)*(1-0.05) -> 321.1 | C9: =B9*0.12 -> 38.532 | D9: =+B9-(74.66*2-20)-C9 -> 153.248 | F9: 2 collares (5% desc.) | G9: =(+G14*2)*(1-0.05) -> 283.1 | H9: =G9*0.12 -> 33.972 | I9: =+G9-(64.66*2-20)-H9 -> 139.808 | K9: =149*2 -> 298
A10: 3 collares (8% desc.) | B10: =(B14*3)*(1-0.05) -> 481.65 | C10: =B10*0.12 -> 57.798 | D10: =+B10-(74.66*3-40)-C10 -> 239.872 | F10: 3 collares (8% desc.) | G10: =(+G14*3)*(1-0.08) -> 411.24 | H10: =G10*0.12 -> 49.3488 | I10: =+G10-(64.66*3-40)-H10 -> 207.9112 | K10: =149*3 -> 447
C12: Comisión | D12: Margen | H12: Comisión | I12: Margen
A13: Con IGV | B13: =B6*1.18 -> 189.80772 | F13: Con IGV | G13: =G6*1.18 -> 171.87172
A14: Precio Final | B14: 169 | C14: =B14*0.12 -> 20.28 | D14: =B14-C14 -> 148.72 | F14: Precio Final | G14: 149
A18: PL01 | F18: PL07
A19: 30% | B19: ='Costos Unitarios'!E25*1.3 -> 0.0975 | F19: 30% | G19: ='Costos Unitarios'!$E$18*1.3 -> 99.658
A20: 40% | B20: ='Costos Unitarios'!E25*1.4 -> 0.105 | F20: 40% | G20: ='Costos Unitarios'!$E$18*1.4 -> 107.324
A21: 0.9 | B21: ='Costos Unitarios'!E25*1.9 -> 0.1425 | F21: 0.9 | G21: ='Costos Unitarios'!$E$18*1.9 -> 145.654
A23: Combos | B23: Precio total (S/) | C23: Comisión | D23: Margen | F23: Combos | G23: Precio total (S/) | H23: Comisión | I23: Margen
A24: 2 velas (5% desc.) | B24: =(B29* 2)*(1-0.05) -> 321.1 | C24: =B24*0.12 -> 38.532 | D24: =+B24-(74.66*2-20)-C24 -> 153.248 | F24: 2 velas (5% desc.) | G24: =(+G29*2)*(1-0.05) -> 283.1 | H24: =G24*0.12 -> 33.972 | I24: =+G24-(64.66*2-20)-H24 -> 139.808 | K24: =149*2 -> 298
A25: 3 velas (8% desc.) | B25: =(B29*3)*(1-0.05) -> 481.65 | C25: =B25*0.12 -> 57.798 | D25: =+B25-(74.66*3-40)-C25 -> 239.872 | F25: 3 velas (8% desc.) | G25: =(+G29*3)*(1-0.08) -> 411.24 | H25: =G25*0.12 -> 49.3488 | I25: =+G25-(64.66*3-40)-H25 -> 207.9112 | K25: =149*3 -> 447
C27: Comisión | D27: Margen | H27: Comisión | I27: Margen
A28: Con IGV | B28: =B21*1.18 -> 0.16815 | F28: Con IGV | G28: =G21*1.18 -> 171.87172
A29: Precio Final | B29: 169 | C29: =B29*0.12 -> 20.28 | D29: =B29-C29 -> 148.72 | F29: Precio Final | G29: 149

Sheet Punto de Equilibrio
A1: Instrucciones: Ingresa tu inversión inicial. Se calcula ganancia porjoya y cuántas vender para cubrirla.
A2: Inversión inicial (S/) | B2: =B15 -> 2855
A3: Costo unitario por joya(S/) | B3: ='Costos Unitarios'!E10 -> 84.66 | C3: =B3*44*12 -> 44700.48
A4: Precio de venta unitario (S/) | B4: ='Precios y Combos'!B6 -> 160.854 | C4: =B4*44*12 -> 84930.912
A5: Ganancia por unidad (S/) | B5: =B4-B3 -> 76.194
A6: Joyas necesarias para equilibrio | B6: =CEILING(B2/B5,1) -> 38
A9: Celular | B9: =40 -> 40
A10: Internet | B10: =15 -> 15
A11: Publicidad | B11: =600 -> 600
A12: Gastos en Publicidad | B12: =1200 -> 1200
A13: Deliverys | B13: 200
A14: Sueldo | B14: 800
B15: =SUM(B9:B14) -> 2855 | C15: =B15*12 -> 34260

Sheet Misión
B3: Entregar joyas petlover como recuerdos que perduran toda la vida
B4: Entregar recuerdos petlover hechos joyas
B8: Productos Estrellas
B9: CL01 | C9: Collar dije circular 1.5cm
B10: CL02 | C10: Collar dije circular 2cm
B11: P07 | C11: Pulsera con hilo negro dije circular
B12: P01 | C12: Pulsera dije circular 2cm colgante
